<mujoco><worldbody><light diffuse=".5 .5 .5" pos="0 0 3" dir="0 0 -1" /><geom name="ground" type="plane" size="5 5 0.1" rgba=".9 .9 .9 1" /><body name="body"><body name="wing0" pos="0 -0.4 0.25" euler="0 0 90"><joint name="wing0link" type="hinge" axis="0 0 1" range="-1 1" /><geom name="wing0" type="cylinder" size="0.2 0.0325" pos="0 0 0" rgba="0 1 0 1" mass="1" /><body name="wing1" euler="0 0 0"><body name="wing2" euler="0 0 0" /><joint name="wing2link" type="hinge" pos="0 0 0" axis="1 0 0" range="-78 78" /><geom name="wing2" type="cylinder" size="0.2 0.0325" pos="-0.8 0 0" rgba="0 1 0 1" mass="1.5" /></body><joint name="wing1link" type="hinge" pos="0 0 0" axis="1 0 0" range="-79 79" /><geom name="wing1" type="cylinder" size="0.2 0.0325" pos="-0.4 0 0" rgba="0 1 0 1" mass="1.5" /></body></body><freejoint name="root" /><geom name="torso" type="box" size="0.5 0.25 0.25" pos="0 0 0.25" rgba="0 0 1 1" mass="0.1" /><body name="wing0" pos="0 0.4 0.25" euler="0 0 90"><joint name="wing0link" type="hinge" axis="0 0 1" range="-1 1" /><geom name="wing0" type="cylinder" size="0.2 0.0325" pos="0 0 0" rgba="0 1 0 1" mass="1" /><body name="wing1" euler="0 0 0"><body name="wing2" euler="0 0 0" /><joint name="wing2link" type="hinge" pos="0 0 0" axis="1 0 0" range="-99 99" /><geom name="wing2" type="cylinder" size="0.2 0.0325" pos="0.8 0 0" rgba="0 1 0 1" mass="1.5" /></body><joint name="wing1link" type="hinge" pos="0 0 0" axis="1 0 0" range="-59 59" /><geom name="wing1" type="cylinder" size="0.2 0.0325" pos="0.4 0 0" rgba="0 1 0 1" mass="1.5" /></body></worldbody><actuator><motor name="wing0m" joint="wing0link" gear="49" ctrllimited="true" ctrlrange="-5 5" /><motor name="wing1m" joint="wing1link" gear="48" ctrllimited="true" ctrlrange="-5 5" /><motor name="wing2m" joint="wing2link" gear="7" ctrllimited="true" ctrlrange="-5 5" /><motor name="wing0m" joint="wing0link" gear="66" ctrllimited="true" ctrlrange="-5 5" /><motor name="wing1m" joint="wing1link" gear="13" ctrllimited="true" ctrlrange="-5 5" /><motor name="wing2m" joint="wing2link" gear="85" ctrllimited="true" ctrlrange="-5 5" /></actuator></mujoco>