<mujoco><worldbody><light diffuse=".5 .5 .5" pos="0 0 3" dir="0 0 -1" /><geom name="ground" type="plane" size="5 5 0.1" rgba=".9 .9 .9 1" /><body name="body"><freejoint name="root" /><geom name="torso" type="box" size="0.5 0.25 0.25" pos="0 0 0.25" rgba="0 0 1 1" mass="0.1" /><body name="wing0" pos="0 0.4 0.25" euler="0 0 90"><joint name="wing0link" type="hinge" axis="0 0 1" range="-1 1" /><geom name="wing0" type="cylinder" size="0.2 0.0325" pos="0 0 0" rgba="0 1 0 1" mass="1" /><body name="wing1" euler="0 0 0"><body name="wing2" euler="0 0 0"><body name="wing3" euler="0 0 0"><body name="wing4" euler="0 0 0"><body name="wing5" euler="0 0 0"><body name="wing6" euler="0 0 0"><body name="wing7" euler="0 0 0"><body name="wing8" euler="0 0 0" /><joint name="wing8link" type="hinge" pos="0 0 0" axis="1 0 0" range="-55 55" /><geom name="wing8" type="cylinder" size="0.2 0.0325" pos="3.2 0 0" rgba="0 1 0 1" mass="1.5" /></body><joint name="wing7link" type="hinge" pos="0 0 0" axis="1 0 0" range="-20 20" /><geom name="wing7" type="cylinder" size="0.2 0.0325" pos="2.8000000000000003 0 0" rgba="0 1 0 1" mass="1.5" /></body><joint name="wing6link" type="hinge" pos="0 0 0" axis="1 0 0" range="-77 77" /><geom name="wing6" type="cylinder" size="0.2 0.0325" pos="2.4000000000000004 0 0" rgba="0 1 0 1" mass="1.5" /></body><joint name="wing5link" type="hinge" pos="0 0 0" axis="1 0 0" range="-53 53" /><geom name="wing5" type="cylinder" size="0.2 0.0325" pos="2.0 0 0" rgba="0 1 0 1" mass="1.5" /></body><joint name="wing4link" type="hinge" pos="0 0 0" axis="1 0 0" range="-44 44" /><geom name="wing4" type="cylinder" size="0.2 0.0325" pos="1.6 0 0" rgba="0 1 0 1" mass="1.5" /></body><joint name="wing3link" type="hinge" pos="0 0 0" axis="1 0 0" range="-33 33" /><geom name="wing3" type="cylinder" size="0.2 0.0325" pos="1.2000000000000002 0 0" rgba="0 1 0 1" mass="1.5" /></body><joint name="wing2link" type="hinge" pos="0 0 0" axis="1 0 0" range="-1 1" /><geom name="wing2" type="cylinder" size="0.2 0.0325" pos="0.8 0 0" rgba="0 1 0 1" mass="1.5" /></body><joint name="wing1link" type="hinge" pos="0 0 0" axis="1 0 0" range="-92 92" /><geom name="wing1" type="cylinder" size="0.2 0.0325" pos="0.4 0 0" rgba="0 1 0 1" mass="1.5" /></body></body></worldbody><actuator><motor name="wing0m" joint="wing0link" gear="79" ctrllimited="true" ctrlrange="-5 5" /><motor name="wing1m" joint="wing1link" gear="29" ctrllimited="true" ctrlrange="-5 5" /><motor name="wing2m" joint="wing2link" gear="80" ctrllimited="true" ctrlrange="-5 5" /><motor name="wing3m" joint="wing3link" gear="59" ctrllimited="true" ctrlrange="-5 5" /><motor name="wing4m" joint="wing4link" gear="43" ctrllimited="true" ctrlrange="-5 5" /><motor name="wing5m" joint="wing5link" gear="79" ctrllimited="true" ctrlrange="-5 5" /><motor name="wing6m" joint="wing6link" gear="76" ctrllimited="true" ctrlrange="-5 5" /><motor name="wing7m" joint="wing7link" gear="71" ctrllimited="true" ctrlrange="-5 5" /><motor name="wing8m" joint="wing8link" gear="2" ctrllimited="true" ctrlrange="-5 5" /></actuator></mujoco>