<mujoco><worldbody><light diffuse=".5 .5 .5" pos="0 0 3" dir="0 0 -1" /><geom name="ground" type="plane" size="5 5 0.1" rgba=".9 .9 .9 1" /><body name="body"><freejoint name="root" /><geom name="torso" type="box" size="0.5 0.25 0.25" pos="0 0 0.25" rgba="0 0 1 1" mass="0.1" /><body name="wing0" pos="0 0.4 0.25" euler="0 0 90"><joint name="wing0link" type="hinge" axis="0 0 1" range="-1 1" /><geom name="wing0" type="cylinder" size="0.2 0.0325" pos="0 0 0" rgba="0 1 0 1" mass="1" /></body><body name="wingl0" pos="0 -0.4 0.25" euler="0 0 90"><joint name="wingl0link" type="hinge" axis="0 0 1" range="-1 1" /><geom name="wingl0" type="cylinder" size="0.2 0.0325" pos="0 0 0" rgba="0 1 0 1" mass="1" /><body name="wingl1" euler="0 0 0"><body name="wingl2" euler="0 0 0"><body name="wingl3" euler="0 0 0" /><joint name="wingl3link" type="hinge" pos="0 0 0" axis="1 0 0" range="-98 98" /><geom name="wingl3" type="cylinder" size="0.2 0.0325" pos="-1.2000000000000002 0 0" rgba="0 1 0 1" mass="1.5" /></body><joint name="wingl2link" type="hinge" pos="0 0 0" axis="1 0 0" range="-39 39" /><geom name="wingl2" type="cylinder" size="0.2 0.0325" pos="-0.8 0 0" rgba="0 1 0 1" mass="1.5" /></body><joint name="wingl1link" type="hinge" pos="0 0 0" axis="1 0 0" range="-67 67" /><geom name="wingl1" type="cylinder" size="0.2 0.0325" pos="-0.4 0 0" rgba="0 1 0 1" mass="1.5" /></body></body></worldbody><actuator><motor name="wing0" joint="wing0link" gear="69" /><motor name="wingl0" joint="wingl0link" gear="77" /><motor name="wingl1" joint="wingl1link" gear="86" /><motor name="wingl2" joint="wingl2link" gear="74" /><motor name="wingl3" joint="wingl3link" gear="47" /></actuator></mujoco>