<mujoco><worldbody><light diffuse=".5 .5 .5" pos="0 0 3" dir="0 0 -1" /><geom name="ground" type="plane" size="5 5 0.1" rgba=".9 .9 .9 1" /><body name="body"><freejoint name="root" /><geom name="torso" type="box" size="0.5 0.25 0.25" pos="0 0 0.25" rgba="0 0 1 1" mass="0.1" /><body name="wing0" pos="0 0.4 0.25" euler="0 0 90"><joint name="wing0link" type="hinge" axis="0 0 1" range="-51 51" /><geom name="wing0" type="cylinder" size="0.2 0.0325" pos="0 0 0" rgba="0 1 0 1" mass="1" /></body></body></worldbody><actuator><motor name="wing0m" joint="wing0link" gear="20" ctrllimited="true" ctrlrange="-5 5" /></actuator></mujoco>