<mujoco><worldbody><light diffuse=".5 .5 .5" pos="0 0 3" dir="0 0 -1" /><geom name="ground" type="plane" size="5 5 0.1" rgba=".9 .9 .9 1" /><body name="body"><freejoint name="root" /><geom name="torso" type="box" size="0.5 0.25 0.25" pos="0 0 0.25" rgba="0 0 1 1" mass="0.01" /><body name="wing0" pos="0 0.4 0.25" euler="0 0 90"><joint name="wing0link" type="hinge" axis="0 1 0" range="-15 15" /><geom name="wing0" type="cylinder" size="0.2 0.0325" pos="0 0 0" rgba="0 1 0 1" mass="1" /><body name="wing1" euler="0 0 0"><body name="wing2" euler="0 0 0"><body name="wing3" euler="0 0 0" /><joint name="wing3link" type="hinge" pos="0 0 0" axis="0 1 0" range="-15 15" /><geom name="wing3" type="cylinder" size="0.2 0.0325" pos="0 0.4 0" rgba="0 1 0 1" mass="1.5" /></body><joint name="wing2link" type="hinge" pos="0 0 0" axis="0 1 0" range="-15 15" /><geom name="wing2" type="cylinder" size="0.2 0.0325" pos="0 0.4 0" rgba="0 1 0 1" mass="1.5" /></body><joint name="wing1link" type="hinge" pos="0 0 0" axis="0 1 0" range="-15 15" /><geom name="wing1" type="cylinder" size="0.2 0.0325" pos="0 0.4 0" rgba="0 1 0 1" mass="1.5" /></body></body></worldbody><actuator><motor name="wing0m" joint="wing0link" gear="8" ctrllimited="true" ctrlrange="-5 5" /><motor name="wing1m" joint="wing1link" gear="8" ctrllimited="true" ctrlrange="-5 5" /><motor name="wing2m" joint="wing2link" gear="8" ctrllimited="true" ctrlrange="-5 5" /><motor name="wing3m" joint="wing3link" gear="8" ctrllimited="true" ctrlrange="-5 5" /></actuator></mujoco>